<?xml version="1.0" ?>
<!-- =================================================================================== -->
<!-- |    This document was autogenerated by xacro from my_robot.xacro                 | -->
<!-- |    EDITING THIS FILE BY HAND IS NOT RECOMMENDED                                 | -->
<!-- =================================================================================== -->
<robot name="my_robot">
  <!---=======Base link===========-->
  <link name="base_link">
    <visual>
      <geometry>
        <box size="1.0 0.5 0.3"/>
      </geometry>
    </visual>
  </link>
  <!---=======Laser link===========-->
  <link name="laser_link">
    <visual>
      <geometry>
        <cylinder length="0.2" radius="0.1"/>
      </geometry>
    </visual>
  </link>
  <joint name="laser_joint" type="fixed">
    <parent link="base_link"/>
    <child link="laser_link"/>
    <origin rpy="0 0 0" xyz="0.5 0 0.3"/>
  </joint>
  <link name="wheel_link">
    <visual>
      <geometry>
        <cylinder length="0.1" radius="0.2"/>
      </geometry>
    </visual>
  </link>
  <joint name="wheel_joint" type="continuous">
    <parent link="base_link"/>
    <child link="wheel_link"/>
    <origin rpy="1.5708 0 0 " xyz="0 -0.3 -0.2"/>
    <axis xyz="0 0 1"/>
  </joint>
</robot>
