<?xml version="1.0"?>

<robot name="my_robot" xmlns:xacro="http://www.ros.org/wiki/xacro">

<xacro:property name="body_length" value="1.0"/>
<xacro:property name="body_width" value="0.5"/>
<xacro:property name="body_height" value="0.3"/>

<!---=======Base link===========-->
<link name="base_link">
	<visual>
		<geometry>
			<box size="${body_length} ${body_width} ${body_height}"/>
		</geometry>
	</visual>	
</link>

<!---=======Laser link===========-->

<link name="laser_link">
	<visual>
		<geometry>
			<cylinder radius="0.1" length="0.2"/>
		</geometry>
	</visual>
</link>

<joint name="laser_joint" type="fixed">
	<parent link="base_link"  /> 
	<child link="laser_link" />
	<origin xyz="0.5 0 0.3" rpy="0 0 0" />
	
</joint>

<link name="wheel_link">
	<visual>
		<geometry>
			<cylinder radius="0.2" length="0.1" />
		</geometry>
	</visual>
</link>

<joint name="wheel_joint" type="continuous">
	<parent link="base_link"/>
	<child link="wheel_link"/>
	<origin xyz="0 -0.3 -0.2" rpy="1.5708 0 0 "/>
	<axis xyz="0 0 1"/>
</joint>

</robot>
